Workbook

Sheet Master
A1: Activate/Deactivate | B1: Count | C1: Object_Type | D1: Column1 | E1: F or T # | F1: Indicator Name | G1: Object ID | H1: Figure ID
A2: Activate | B2: 1 | C2: Table | E2: T1 | F2: Demographic Summary by Municipality, 2023 | G2: tbl-demographics-sum | H2: =IF(LEFT(Table3[[#This Row],[Object ID]],4)="tbl-","fig-" & MID(Table3[[#This Row],[Object ID]],5,LEN(Table3[[#This Row],[Object ID]])-4),"") -> fig-demographics-sum
A3: Activate | B3: 2 | C3: Table | E3: T2 | F3: Population by Municipality, 1970–2020 | G3: tbl-pop | H3: =IF(LEFT(Table3[[#This Row],[Object ID]],4)="tbl-","fig-" & MID(Table3[[#This Row],[Object ID]],5,LEN(Table3[[#This Row],[Object ID]])-4),"") -> fig-pop
A4: Activate | B4: 3 | C4: Figure | E4: F1 | F4: Total Population by Municipality, 2023 | G4: tbl-total-pop | H4: =IF(LEFT(Table3[[#This Row],[Object ID]],4)="tbl-","fig-" & MID(Table3[[#This Row],[Object ID]],5,LEN(Table3[[#This Row],[Object ID]])-4),"") -> fig-total-pop
A5: Activate | B5: 4 | C5: Table | E5: T3 | F5: Population Growth by Municipality, 2000–2020 | G5: tbl-pop-growth | H5: =IF(LEFT(Table3[[#This Row],[Object ID]],4)="tbl-","fig-" & MID(Table3[[#This Row],[Object ID]],5,LEN(Table3[[#This Row],[Object ID]])-4),"") -> fig-pop-growth
A6: Activate | B6: 5 | C6: Table | E6: T4 | F6: Population and Housing Unit Density by Municipality, 2023 | G6: tbl-pop-housing-density | H6: =IF(LEFT(Table3[[#This Row],[Object ID]],4)="tbl-","fig-" & MID(Table3[[#This Row],[Object ID]],5,LEN(Table3[[#This Row],[Object ID]])-4),"") -> fig-pop-housing-density
A7: Activate | B7: 6 | C7: Table | E7: T5 | F7: Population of Municipalities by Sex and Age, 2023 | G7: tbl-pop-sex-age | H7: =IF(LEFT(Table3[[#This Row],[Object ID]],4)="tbl-","fig-" & MID(Table3[[#This Row],[Object ID]],5,LEN(Table3[[#This Row],[Object ID]])-4),"") -> fig-pop-sex-age
A8: Activate | B8: 7 | C8: Figure | E8: F2 | F8: Median Age by Municipality, 2023 | G8: tbl-median-age | H8: =IF(LEFT(Table3[[#This Row],[Object ID]],4)="tbl-","fig-" & MID(Table3[[#This Row],[Object ID]],5,LEN(Table3[[#This Row],[Object ID]])-4),"") -> fig-median-age
A9: Activate | B9: 8 | C9: Table | E9: T6 | F9: Population of Municipalities by Race and Ethnicity, 2020 | G9: tbl-pop-race-ethnicity | H9: =IF(LEFT(Table3[[#This Row],[Object ID]],4)="tbl-","fig-" & MID(Table3[[#This Row],[Object ID]],5,LEN(Table3[[#This Row],[Object ID]])-4),"") -> fig-pop-race-ethnicity
A10: Activate | B10: 9 | C10: Table | E10: T7 | F10: Employed Civilians by Industry and Municipality, 2023 | G10: tbl-employed-civilians-industry | H10: =IF(LEFT(Table3[[#This Row],[Object ID]],4)="tbl-","fig-" & MID(Table3[[#This Row],[Object ID]],5,LEN(Table3[[#This Row],[Object ID]])-4),"") -> fig-employed-civilians-industry
A11: Activate | B11: 10 | C11: Table | E11: T8 | F11: Employed Civilian Occupations by Municipality, 2023 | G11: tbl-employed-civilian-occupations | H11: =IF(LEFT(Table3[[#This Row],[Object ID]],4)="tbl-","fig-" & MID(Table3[[#This Row],[Object ID]],5,LEN(Table3[[#This Row],[Object ID]])-4),"") -> fig-employed-civilian-occupations
A12: Activate | B12: 11 | C12: Table | E12: T9 | F12: All-Cause Mortality, Rate per 100,000 Population by Age, ZIP Code, Race and Ethnicity, 2020–2023 | G12: tbl-all-cause-mortal-rate-age-zip-code-rande | H12: =IF(LEFT(Table3[[#This Row],[Object ID]],4)="tbl-","fig-" & MID(Table3[[#This Row],[Object ID]],5,LEN(Table3[[#This Row],[Object ID]])-4),"") -> fig-all-cause-mortal-rate-age-zip-code-rande
A13: Activate | B13: 12 | C13: Figure | E13: F3 | F13: All-Cause Mortality, Age-Adjusted Rate per 100,000 Population by Race and Ethnicity, 2020–2022 | G13: tbl-all-cause-mortal-aar-rande | H13: =IF(LEFT(Table3[[#This Row],[Object ID]],4)="tbl-","fig-" & MID(Table3[[#This Row],[Object ID]],5,LEN(Table3[[#This Row],[Object ID]])-4),"") -> fig-all-cause-mortal-aar-rande
... A127: Activate | B127: 126 | C127: Figure | E127: F89 | F127: Prostate Cancer Mortality, Age-Adjusted Rate per 100,000 Population by Race and Ethnicity, 2018–2022 | G127: tbl-prostate-mortal-rande-aar-five | H127: =IF(LEFT(Table3[[#This Row],[Object ID]],4)="tbl-","fig-" & MID(Table3[[#This Row],[Object ID]],5,LEN(Table3[[#This Row],[Object ID]])-4),"") -> fig-prostate-mortal-rande-aar-five
C128: Table | E128: T38 | F128: General Communicable Diseases, Case Counts and Rates per 100,000 Residents, 2021–2023 | G128: tbl-cd-count-rate | H128: =IF(LEFT(Table3[[#This Row],[Object ID]],4)="tbl-","fig-" & MID(Table3[[#This Row],[Object ID]],5,LEN(Table3[[#This Row],[Object ID]])-4),"") -> fig-cd-count-rate
C129: Figure | E129: F90 | F129: Hepatitis A, Rate per 100,000 Population, 2020–2023 | G129: tbl-hepatitisa-rate | H129: =IF(LEFT(Table3[[#This Row],[Object ID]],4)="tbl-","fig-" & MID(Table3[[#This Row],[Object ID]],5,LEN(Table3[[#This Row],[Object ID]])-4),"") -> fig-hepatitisa-rate
A130: Activate | B130: 127 | C130: Figure | E130: F91 | F130: Chronic Hepatitis B, Rate per 100,000 Population, 2020–2023 | G130: tbl-hepatitisb-chronic-rate | H130: =IF(LEFT(Table3[[#This Row],[Object ID]],4)="tbl-","fig-" & MID(Table3[[#This Row],[Object ID]],5,LEN(Table3[[#This Row],[Object ID]])-4),"") -> fig-hepatitisb-chronic-rate
A131: Activate | B131: 128 | C131: Figure | E131: F92 | F131: Acute Hepatitis C, Rate per 100,000 Population, 2020–2023 | G131: tbl-hepatitisc-acute-rate | H131: =IF(LEFT(Table3[[#This Row],[Object ID]],4)="tbl-","fig-" & MID(Table3[[#This Row],[Object ID]],5,LEN(Table3[[#This Row],[Object ID]])-4),"") -> fig-hepatitisc-acute-rate
A132: Activate | B132: 129 | C132: Figure | E132: F93 | F132: Chronic Hepatitis C, Rate per 100,000 Population, 2020–2023 | G132: tbl-hepatitisc-chronic-rate | H132: =IF(LEFT(Table3[[#This Row],[Object ID]],4)="tbl-","fig-" & MID(Table3[[#This Row],[Object ID]],5,LEN(Table3[[#This Row],[Object ID]])-4),"") -> fig-hepatitisc-chronic-rate
A133: Activate | B133: 130 | C133: Table | E133: T40 | F133: Chlamydia, Case Counts and Infection Rates per 100,000 by Sex, Race and Ethnicity, Age, and ZIP Code, 2021–2024 | G133: tbl-chlamydia-count-rate-sex-rande-age-zip | H133: =IF(LEFT(Table3[[#This Row],[Object ID]],4)="tbl-","fig-" & MID(Table3[[#This Row],[Object ID]],5,LEN(Table3[[#This Row],[Object ID]])-4),"") -> fig-chlamydia-count-rate-sex-rande-age-zip
A134: Activate | B134: 131 | C134: Figure | E134: F94 | F134: Chlamydia, Age-Adjusted Rate per 100,000 Population, 2020–2023 | G134: tbl-chlamydia-aar | H134: =IF(LEFT(Table3[[#This Row],[Object ID]],4)="tbl-","fig-" & MID(Table3[[#This Row],[Object ID]],5,LEN(Table3[[#This Row],[Object ID]])-4),"") -> fig-chlamydia-aar
A135: Activate | B135: 132 | C135: Figure | E135: F95 | F135: Chlamydia, Rate per 100,000 Population by Race and Ethnicity, 2021–2024 | G135: tbl-chlamydia-rande | H135: =IF(LEFT(Table3[[#This Row],[Object ID]],4)="tbl-","fig-" & MID(Table3[[#This Row],[Object ID]],5,LEN(Table3[[#This Row],[Object ID]])-4),"") -> fig-chlamydia-rande
A136: Activate | B136: 133 | C136: Table | E136: T41 | F136: Gonorrhea, Case Counts and Infection Rates per 100,000 by Sex, Race and Ethnicity, Age, and ZIP Code, 2021–2024 | G136: tbl-gonorrhea-count-rate-sex-rande-age-zip | H136: =IF(LEFT(Table3[[#This Row],[Object ID]],4)="tbl-","fig-" & MID(Table3[[#This Row],[Object ID]],5,LEN(Table3[[#This Row],[Object ID]])-4),"") -> fig-gonorrhea-count-rate-sex-rande-age-zip
A137: Activate | B137: 134 | C137: Figure | E137: F96 | F137: Gonorrhea, Age-Adjusted Case Rate per 100,000 Population, 2020–2023 | G137: tbl-gonorrhea-aar | H137: =IF(LEFT(Table3[[#This Row],[Object ID]],4)="tbl-","fig-" & MID(Table3[[#This Row],[Object ID]],5,LEN(Table3[[#This Row],[Object ID]])-4),"") -> fig-gonorrhea-aar
A138: Activate | B138: 135 | C138: Figure | E138: F97 | F138: Gonorrhea, Case Rate per 100,000 Population by Race and Ethnicity, 2021–2024 | G138: tbl-gonorrhea-rande | H138: =IF(LEFT(Table3[[#This Row],[Object ID]],4)="tbl-","fig-" & MID(Table3[[#This Row],[Object ID]],5,LEN(Table3[[#This Row],[Object ID]])-4),"") -> fig-gonorrhea-rande
A139: Activate | B139: 136 | C139: Table | E139: T42 | F139: HIV Prevalence, Rate per 100,000 Population by Race and Ethnicity, Age, and Sex, 2020–2023 | G139: tbl-hiv-prevalence-rate-rande-age-sex | H139: =IF(LEFT(Table3[[#This Row],[Object ID]],4)="tbl-","fig-" & MID(Table3[[#This Row],[Object ID]],5,LEN(Table3[[#This Row],[Object ID]])-4),"") -> fig-hiv-prevalence-rate-rande-age-sex
A140: Activate | B140: 137 | C140: Figure | E140: F98 | F140: HIV and AIDS Incidence, Age-Adjusted Rate per 100,000 Population, 2020–2023 | G140: tbl-hiv-aids-incidence-aar | H140: =IF(LEFT(Table3[[#This Row],[Object ID]],4)="tbl-","fig-" & MID(Table3[[#This Row],[Object ID]],5,LEN(Table3[[#This Row],[Object ID]])-4),"") -> fig-hiv-aids-incidence-aar
A141: Activate | B141: 138 | C141: Figure | E141: F99 | F141: HIV Prevalence by Transmission Category, Count, 2020–2023 | G141: tbl-hiv-prevalence-transmission-category | H141: =IF(LEFT(Table3[[#This Row],[Object ID]],4)="tbl-","fig-" & MID(Table3[[#This Row],[Object ID]],5,LEN(Table3[[#This Row],[Object ID]])-4),"") -> fig-hiv-prevalence-transmission-category
... A175: Activate | B175: 172 | C175: Figure | E175: F125 | F175: Percentage of Opioid Naïve Patients Receiving More than a 7-Day Supply, 2021–2024 | G175: tbl-opioid-naïve-7day-rx | H175: =IF(LEFT(Table3[[#This Row],[Object ID]],4)="tbl-","fig-" & MID(Table3[[#This Row],[Object ID]],5,LEN(Table3[[#This Row],[Object ID]])-4),"") -> fig-opioid-naïve-7day-rx
C176: Figure | E176: F126 | F176: Benzodiazepine Prescriptions, Age-Adjusted Rate per 1,000 Person-Years, 2021–2024 | G176: tbl-benzo-rx-aar | H176: =IF(LEFT(Table3[[#This Row],[Object ID]],4)="tbl-","fig-" & MID(Table3[[#This Row],[Object ID]],5,LEN(Table3[[#This Row],[Object ID]])-4),"") -> fig-benzo-rx-aar
A177: Activate | B177: 173 | C177: Figure | E177: F127 | F177: Percentage of Patients With Overlapping Opioid Analgesic and Benzodiazepine Prescriptions, 2021–2024 | G177: tbl-overlap-opioid-benzo-rx | H177: =IF(LEFT(Table3[[#This Row],[Object ID]],4)="tbl-","fig-" & MID(Table3[[#This Row],[Object ID]],5,LEN(Table3[[#This Row],[Object ID]])-4),"") -> fig-overlap-opioid-benzo-rx
A178: Activate | B178: 174 | C178: Figure | E178: F128 | F178: Patients Who Received at Least One Buprenorphine Prescription for Opioid Use Disorder, Age-Adjusted Rate per 100,000 Population, 2021–2024 | G178: tbl-opioidud-atleast1rx-bup-aar | H178: =IF(LEFT(Table3[[#This Row],[Object ID]],4)="tbl-","fig-" & MID(Table3[[#This Row],[Object ID]],5,LEN(Table3[[#This Row],[Object ID]])-4),"") -> fig-opioidud-atleast1rx-bup-aar
A179: Activate | B179: 175 | C179: Figure | E179: F129 | F179: Percentage of Patients Receiving Continuous Buprenorphine for Treatment of Opioid Use Disorder, 2021–2024 | G179: tbl-opioidud-continuous-bup-rx | H179: =IF(LEFT(Table3[[#This Row],[Object ID]],4)="tbl-","fig-" & MID(Table3[[#This Row],[Object ID]],5,LEN(Table3[[#This Row],[Object ID]])-4),"") -> fig-opioidud-continuous-bup-rx
A180: Activate | B180: 176 | C180: Figure | E180: F130 | F180: Percentage Perception of Harm of Substance use, Moderate Risk or Great Risk, 2025 | G180: tbl-perception-harm-su | H180: =IF(LEFT(Table3[[#This Row],[Object ID]],4)="tbl-","fig-" & MID(Table3[[#This Row],[Object ID]],5,LEN(Table3[[#This Row],[Object ID]])-4),"") -> fig-perception-harm-su
A181: Activate | B181: 177 | C181: Table | E181: T51 | F181: Lifetime Use of Substance by Grade | G181: tbl-lifetime-su | H181: =IF(LEFT(Table3[[#This Row],[Object ID]],4)="tbl-","fig-" & MID(Table3[[#This Row],[Object ID]],5,LEN(Table3[[#This Row],[Object ID]])-4),"") -> fig-lifetime-su
A182: Activate | B182: 178 | C182: Table | E182: T52 | F182: Past 30 Day Use of Substance by Grade | G182: tlb-past-30day-su | H182: =IF(LEFT(Table3[[#This Row],[Object ID]],4)="tbl-","fig-" & MID(Table3[[#This Row],[Object ID]],5,LEN(Table3[[#This Row],[Object ID]])-4),"")
A183: Activate | B183: 179 | C183: Table | E183: T53 | F183: Percentage of Sources of Marijuana for Those Who Reported Use | G183: tbl-source-marijuana-ifused | H183: =IF(LEFT(Table3[[#This Row],[Object ID]],4)="tbl-","fig-" & MID(Table3[[#This Row],[Object ID]],5,LEN(Table3[[#This Row],[Object ID]])-4),"") -> fig-source-marijuana-ifused
A184: Activate | B184: 180 | C184: Table | E184: T54 | F184: Opioid-Related Overdose Fatalities, Rate per 100,000 Population by Age and Sex, 2021–2024 | G184: tbl-opioid-od-fatal-age-sex | H184: =IF(LEFT(Table3[[#This Row],[Object ID]],4)="tbl-","fig-" & MID(Table3[[#This Row],[Object ID]],5,LEN(Table3[[#This Row],[Object ID]])-4),"") -> fig-opioid-od-fatal-age-sex
A185: Activate | B185: 181 | C185: Figure | E185: F131 | F185: Opioid-Related Overdose Fatalities, Rate per 100,000 Population, 2021–2024 | G185: tbl-opioid-od-fatal | H185: =IF(LEFT(Table3[[#This Row],[Object ID]],4)="tbl-","fig-" & MID(Table3[[#This Row],[Object ID]],5,LEN(Table3[[#This Row],[Object ID]])-4),"") -> fig-opioid-od-fatal
A186: Activate | B186: 182 | C186: Figure | E186: F132 | F186: Opioid-Related Overdose Fatalities, Rate per 100,000 Population by Age, 2021–2024 | G186: tbl-opioid-od-fatal-age | H186: =IF(LEFT(Table3[[#This Row],[Object ID]],4)="tbl-","fig-" & MID(Table3[[#This Row],[Object ID]],5,LEN(Table3[[#This Row],[Object ID]])-4),"") -> fig-opioid-od-fatal-age
...

Sheet Dropdowns
A1: integer | B1: Y-labels | D1: Footnotes | E1: Sources | F1: Links
A2: number | B2: Case Rate | C2: * | D2: *: BRFSS - Crude rate is unreliable due to large standard error. | E2: Source: Centers for Disease Control and Prevention | F2: https://health.data.ny.gov/Health/Behavioral-Risk-Factor-Surveillance-System-BRFSS-H/jsy7-eb4n/data
A3: percent1 | B3: Index | C3: * | D3: *: BRFSS - Percentage is unreliable due to large standard error. | E3: Source: Community Partner Survey Focus Groups | F3: https://www.cdc.gov/places/
A4: percent2 | B4: Number of Cases | C4: * | D4: *: Data are unstable due to a margin of error greater than 10%. | E4: Source: Feeding America | F4: https://webbi1.health.ny.gov/SASStoredProcess/guest?_program=%2FEBI%2FPHIG%2Fapps%2Fchir_dashboard%2Fchir_dashboard&p=ch&cos=33
A5: currency | B5: Percent | C5: * | D5: *: Data are unstable due to fewer than 10 events in the numerator. | E5: Source: Health Resources and Services Administration Data Warehouse | F5: https://www.health.ny.gov/statistics/community/minority/county/orange.htm
A6: currency2 | B6: Rate per 1,000 | C6: * | D6: *: Data are unstable due to fewer than 20 events in the numerator. | E6: Source: NYC Poison Center | F6: https://www.health.ny.gov/statistics/diseases/communicable/docs/2019_hepc_regional.pdf
A7: ratio | B7: Rate per 10,000 | C7: * | D7: *: The percentage is unstable. | E7: Source: NYS Board of Elections | F7: https://www.health.ny.gov/statistics/chac/perinatal/county/2018-2020/orange.htm
A8: date | B8: Rate per 100,000 | C8: * | D8: *: The rate is unstable. | E8: Source: NYS Cancer Registry and Cancer Statistics | F8: https://www.criminaljustice.ny.gov/crimnet/ojsa/arrests/index.htm
A9: text | B9: Ratio | C9: + | D9: : The 2019 ED data in NYC may be incomplete and subject to change. Thus, the state rates may be underestimated and subject to change. | E9: Source: NYS Community Health Indicator Reports Dashboard | F9: https://data.nysed.gov/gradrate.php?year=2022&county=44
C10: Other | D10: Other (please specify): Some additional responses from participants include access to healthy affordable food, transportation, valuing health as a family priority, affordable housing, lack of chronic disease self-management programs, lack of social support systems, language barriers. | E10: Source: NYS County Health Indicators by Race and Ethnicity | F10: https://webbi1.health.ny.gov/SASStoredProcess/guest?_program=%2FEBI%2FPHIG%2Fapps%2Fmch_dashboard%2Fmch_dashboard&p=ch&cos=33
C11: Other | D11: Other (please specify): Some additional responses from participants include finding child care, access to health care providers who are trained in LGBTQIA+ health care needs, mental health services, immigration issues, language and cultural barriers, and financial issues. | E11: Source: NYS Department of Health Office of Sexual Health and Epidemiology | F11: https://webbi1.health.ny.gov/SASStoredProcess/guest?_program=%2FEBI%2FPHIG%2Fapps%2Fopioid_dashboard%2Fop_dashboard&p=ch&cos=33
C12: Other | D12: Other (please specify): Some additional responses from participants include location of services, lack of financial resources, transportation, affordable housing, and service providers not being aware of biases they bring into marginalized communities. | E12: Source: NYS Division of Criminal Justice Services | F12: https://webbi1.health.ny.gov/SASStoredProcess/guest?_program=%2FEBI%2FPHIG%2Fapps%2Fdashboard%2Fpa_dashboard&p=ch&cos=33
C13: Other | D13: Other (please specify): Some additional responses from participants include navigating health care access, poverty, affordable transportation, and accessibility and availability of quality services. | E13: Source: NYS Education Department | F13: https://www.health.ny.gov/statistics/diseases/communicable/std/docs/sti_surveillance_report_2021.pdf
C14: Other | D14: Other (please specify): Some additional responses from participants include stigma, language barrier as a large portion of the population being served speaks Spanish, navigating the health system, and places to play and/or exercise. | E14: Source: NYS Leading Causes of Death Dashboard | F14: https://statecancerprofiles.cancer.gov/
C15: s | D15: s: Data are suppressed due to unreliable or missing data. | E15: Source: NYS Opioid Data Dashboard | F15: https://data.census.gov/cedsci/
C16: s | D16: s: Data are suppressed due to not meeting reporting criteria. | E16: Source: NYS Prevention Agenda Tracking Dashboard | F16: https://www.americashealthrankings.org/
C17: s | D17: s: Data are suppressed due to lack of preliminary data. | E17: Source: NYS Smoker's Quitline | F17: https://ahead.hiv.gov/
C18: s | D18: s: Data are suppressed due to not meeting confidentialty criteria. | E18: Source: NYSDOH Behavioral Risk Factor Surveillance System | F18: https://wonder.cdc.gov/
C19: s | D19: s: Data are suppressed due to small sample size. | E19: Source: NYSDOH Bureau of Communicable Disease Control | F19: https://nccd.cdc.gov/Youthonline/App/Results.aspx?LID=XX
E20: Source: NYSDOH Communicable Disease Annual Reports | F20: https://www.cdc.gov/injury/wisqars/index.html
E21: Source: NYSDOH Communicable Disease Electronic Surveillance System | F21: https://www.cdc.gov/mmwr/index.html
E22: Source: NYSDOH, Wadsworth Center Rabies Laboratory | F22: https://www.cdc.gov/asthma/asthmadata.htm
E23: Source: United for ALICE | F23: https://www.cdc.gov/nceh/
E24: Source: University of Wisconsin Population Health Institute. County Health Rankings & Roadmaps | F24: https://www.cdc.gov/nchs/index.htm
E25: Source: Upstate NY Poison Center | F25: https://www.cdc.gov/nchs/nhis/shs.htm
E26: Source: US Census Bureau | F26: https://www.cdc.gov/diabetes/data/index.html
E27: Source: US Census Bureau; American Community Survey | F27: https://www.cdc.gov/nchhstp/atlas/index.htm
E28: Source: Vital Statistics of NYS | F28: https://www.cdc.gov/std/statistics/2021/default.htm
F29: https://www.cdc.gov/vaccines/imz-managers/coverage/teenvaxview/data-reports/index.html
F30: https://gis.cdc.gov/grasp/diabetes/diabetesatlas-surveillance.html
F31: https://www.cdc.gov/hepatitis/statistics/SurveillanceRpts.htm
F32: https://www.ghrconnects.org/indicators
F33: https://www.kff.org/
F34: https://progressreport.cancer.gov/detection
F35: https://statecancerprofiles.cancer.gov/index.html
F36: https://nces.ed.gov/
F37: https://www.niaaa.nih.gov/
F38: https://data.oecd.org/
F39: https://data.census.gov/cedsci/
F40: https://www.bls.gov/cps/data-overview.htm
...

Sheet Demographic Summary
A1: Name | B1: Demographic Summary by Municipality, 2023
A2: Table/Figure/Both | B2: Both
A3: Object ID | B3: =IF($B$1="","",_xlfn.XLOOKUP($B$1,Master!$F$2:$F$321,Master!$G$2:$G$321,"")) -> tbl-demographics-sum
A4: Figure ID | B4: =IF($B$1="","",_xlfn.XLOOKUP($B$1,Master!$F$2:$F$321,Master!$H$2:$H$321,"")) -> fig-demographics-sum | F4: text | G4: number | H4: number | I4: number | J4: number | K4: number | L4: number | M4: number | N4: percent1
A5: Table Rules | E5: Enter Data | F5: Geographic Area | G5: Population | H5: Age | L5: Sex | N5: Median Age
A6: Multilevel Headers | B6: TRUE | G6: Total | H6: 0-17 year | I6: 18-24 years | J6: 25-64 years | K6: 65+ years | L6: Male | M6: Female
F7: Orange County | G7: 403840 | H7: 103740 | I7: 41468 | J7: 200687 | K7: 57945 | L7: 201512 | M7: 202328 | N7: 36.9
F8: Blooming Grove Town | G8: 18672 | H8: 5333 | I8: 1742 | J8: 9322 | K8: 2275 | L8: 9133 | M8: 9539 | N8: 34.4
A9: Figure Rules | F9: South Blooming Grove Village | G9: 3880 | H9: 1658 | I9: 263 | J9: 1622 | K9: 337 | L9: 1933 | M9: 1947 | N9: 25.2
A10: Figure Type | F10: Washingtonville Village | G10: 5723 | H10: 1287 | I10: 430 | J10: 3121 | K10: 885 | L10: 2883 | M10: 2840 | N10: 39.1
A11: X Column | F11: Chester Town | G11: 12621 | H11: 2702 | I11: 1198 | J11: 6927 | K11: 1794 | L11: 5839 | M11: 6782 | N11: 39.1
A12: Y Column | F12: Chester Village | G12: 4052 | H12: 738 | I12: 313 | J12: 2451 | K12: 550 | L12: 1961 | M12: 2,091 | N12: 36.5
A13: X Axis Title | F13: Cornwall Town | G13: 12801 | H13: 2714 | I13: 1148 | J13: 6435 | K13: 2504 | L13: 6218 | M13: 6,583 | N13: 42.4
A14: Y Axis Title | F14: Cornwall-on-Hudson Village | G14: 3046 | H14: 593 | I14: 321 | J14: 1580 | K14: 552 | L14: 1460 | M14: 1586 | N14: 44.7
A15: Start at Zero | F15: Crawford Town | G15: 9097 | H15: 2086 | I15: 814 | J15: 5014 | K15: 1183 | L15: 4732 | M15: 4365 | N15: 40.8
A16: Pivot For Chart | F16: Deerpark Town | G16: 7471 | H16: 1512 | I16: 508 | J16: 3786 | K16: 1665 | L16: 3753 | M16: 3718 | N16: 45.4
F17: Goshen Town | G17: 14463 | H17: 2871 | I17: 1226 | J17: 7303 | K17: 3063 | L17: 7390 | M17: 7073 | N17: 44.7
A18: Source Specifications | F18: Goshen Village | G18: 5751 | H18: 1108 | I18: 367 | J18: 2744 | K18: 1532 | L18: 2745 | M18: 3006 | N18: 48
A19: Source | B19: Source: US Census Bureau, American Community Survey, 2019–2023 5-Year Population Estimates, Table DP05-Demographic and Housing Estimates, November 2025 https://data.census.gov/table/ACSDP5Y2023.DP05?q=DP05+Orange+County,+NY&g=050XX00US36071 | F19: Greenville Town | G19: 4680 | H19: 1167 | I19: 266 | J19: 2637 | K19: 610 | L19: 2458 | M19: 2222 | N19: 37.8
F20: Hamptonburgh Town | G20: 5507 | H20: 1280 | I20: 499 | J20: 2943 | K20: 785 | L20: 2924 | M20: 2583 | N20: 44.3
A21: Note Specfications | F21: Highlands Town | G21: 12,894 | H21: 3,027 | I21: 3,203 | J21: 5,600 | K21: 1,064 | L21: 7,397 | M21: 5,497 | N21: 27.2
A22: Note | B22: Note: Town totals include Village totals. The Village of Harriman is split between the Towns of Monroe and Woodbury. | F22: Highland Falls Village | G22: 3,696 | H22: 773 | I22: 278 | J22: 2,198 | K22: 447 | L22: 2,000 | M22: 1,696 | N22: 40.7
F23: Middletown City | G23: 30,227 | H23: 7,796 | I23: 2,553 | J23: 15768 | K23: 4110 | L23: 15640 | M23: 14587 | N23: 35.7
F24: Minisink Town | G24: 4,648 | H24: 1,277 | I24: 476 | J24: 2371 | K24: 524 | L24: 2246 | M24: 2402 | N24: 36.5
F25: Unionville Village | G25: 684 | H25: 222 | I25: 79 | J25: 304 | K25: 79 | L25: 282 | M25: 402 | N25: 30.5
F26: Monroe Town | G26: 21,299 | H26: 5,787 | I26: 2,035 | J26: 10438 | K26: 3039 | L26: 9782 | M26: 11517 | N26: 36.8
F27: Harriman Village (portion) | G27: 2089 | H27: 598 | I27: 95 | J27: 1033 | K27: 363 | L27: 877 | M27: 1212 | N27: 37
F28: Monroe Village | G28: 9466 | H28: 2552 | I28: 1,118 | J28: 4846 | K28: 950 | L28: 4473 | M28: 4993 | N28: 32.8
F29: Montgomery Town | G29: 23235 | H29: 5597 | I29: 2,052 | J29: 12228 | K29: 3358 | L29: 11058 | M29: 12177 | N29: 39.4
F30: Maybrook Village | G30: 3147 | H30: 507 | I30: 208 | J30: 1772 | K30: 660 | L30: 1451 | M30: 1696 | N30: 46.5
F31: Montgomery Village | G31: 3800 | H31: 962 | I31: 325 | J31: 1960 | K31: 553 | L31: 1722 | M31: 2078 | N31: 39.8
F32: Walden Village | G32: 6871 | H32: 1664 | I32: 659 | J32: 3732 | K32: 816 | L32: 3498 | M32: 3373 | N32: 38.1
F33: Mount Hope Town | G33: 6,500 | H33: 1,080 | I33: 485 | J33: 3856 | K33: 1079 | L33: 3897 | M33: 2603 | N33: 44.3
F34: Otisville Village | G34: 1210 | H34: 353 | I34: 56 | J34: 564 | K34: 237 | L34: 623 | M34: 587 | N34: 35.6
F35: Newburgh City | G35: 28649 | H35: 7379 | I35: 3,337 | J35: 14393 | K35: 3540 | L35: 13424 | M35: 15225 | N35: 31.7
F36: Newburgh Town | G36: 31866 | H36: 6121 | I36: 2,988 | J36: 17297 | K36: 5460 | L36: 16112 | M36: 15754 | N36: 41.8
F37: New Windsor Town | G37: 27781 | H37: 5691 | I37: 2,448 | J37: 15049 | K37: 4593 | L37: 13475 | M37: 14306 | N37: 41.4
F38: Palm Tree Town | G38: 36572 | H38: 20811 | I38: 5,257 | J38: 9535 | K38: 969 | L38: 18558 | M38: 18014 | N38: 15.1
F39: Kiryas Joel Village | G39: 36,572 | H39: 20,811 | I39: 5,257 | J39: 9535 | K39: 969 | L39: 18558 | M39: 18014 | N39: 15.1
F40: Port Jervis City | G40: 8,709 | H40: 1,809 | I40: 1,076 | J40: 4209 | K40: 1615 | L40: 4267 | M40: 4442 | N40: 39.6
...

Sheet Population by Municipality
A1: Name | B1: Population by Municipality, 1970–2020
A2: Table/Figure/Both | B2: Both
A3: Object ID | B3: =IF($B$1="","",_xlfn.XLOOKUP($B$1,Master!$F$2:$F$321,Master!$G$2:$G$321,"")) -> tbl-pop
A4: Figure ID | B4: =IF($B$1="","",_xlfn.XLOOKUP($B$1,Master!$F$2:$F$321,Master!$H$2:$H$321,"")) -> fig-pop | F4: text | G4: number | H4: number | I4: number | J4: number | K4: number | L4: number
A5: Table Rules | E5: Enter Data | F5: Geographic Area | G5: Population
A6: Multilevel Headers | G6: 1970 | H6: 1980 | I6: 1990 | J6: 2000 | K6: 2010 | L6: 2020
F7: Orange County | G7: 221657 | H7: 259603 | I7: 307647 | J7: 341367 | K7: 372813 | L7: 401310
F8: Blooming Grove Town | G8: 8813 | H8: 12339 | I8: 16673 | J8: 17351 | K8: 18028 | L8: 18811
A9: Figure Rules | F9: South Blooming Grove Village | G9: N/A | H9: N/A | I9: N/A | J9: N/A | K9: 3234 | L9: 3973
A10: Figure Type | F10: Washingtonville Village | G10: 1887 | H10: 2380 | I10: 4906 | J10: 5851 | K10: 5899 | L10: 5657
A11: X Column | F11: Chester Town | G11: 4767 | H11: 6850 | I11: 9138 | J11: 12140 | K11: 11981 | L11: 12646
A12: Y Column | F12: Chester Village | G12: 1627 | H12: 1910 | I12: 3270 | J12: 3445 | K12: 3969 | L12: 3993
A13: X Axis Title | F13: Cornwall Town | G13: 9672 | H13: 10774 | I13: 11270 | J13: 12307 | K13: 12646 | L13: 12884
A14: Y Axis Title | F14: Cornwall-on-Hudson Village | G14: 3131 | H14: 3164 | I14: 3093 | J14: 3058 | K14: 3018 | L14: 3075
A15: Start at Zero | F15: Crawford Town | G15: 3896 | H15: 4910 | I15: 6394 | J15: 7875 | K15: 9316 | L15: 9130
A16: Pivot For Chart | F16: Deerpark Town | G16: 4370 | H16: 5633 | I16: 7832 | J16: 7858 | K16: 7901 | L16: 7509
F17: Goshen Town | G17: 8393 | H17: 10463 | I17: 11500 | J17: 12913 | K17: 13687 | L17: 14571
A18: Source Specifications | F18: Goshen Village | G18: 4342 | H18: 4874 | I18: 5255 | J18: 5676 | K18: 5454 | L18: 5777
A19: Source | B19: Source: US Census Bureau, 2020 Decennial Redistricting Data (PL 94-171), Table P1-Total Population, November 2025 https://data.census.gov/table/DECENNIALPL2020.P1?q=PL+94-171&g=050XX00US36071 | F19: Greenville Town | G19: 1379 | H19: 2085 | I19: 3120 | J19: 3800 | K19: 4616 | L19: 4689
F20: Hamptonburgh Town | G20: 2204 | H20: 2945 | I20: 3910 | J20: 4686 | K20: 5561 | L20: 5489
A21: Note Specfications | F21: Highlands Town | G21: 14661 | H21: 14004 | I21: 13667 | J21: 12484 | K21: 12492 | L21: 12939
A22: Note | B22: Note: Town totals include Village totals; Village of Kiryas Joel was incorporated in 1977; Villages of South Blooming Grove and Woodbury were incorporated in 2006; Town of Palm Tree was incorporated in 2017 and made coterminous to the Village of Kiryas Joel thereafter. Prior to incorporation of Town of Palm Tree, the Village of Kiryas Joel was incorporated within the boundaries of the Town of Monroe | F22: Highland Falls Village | G22: 4638 | H22: 4187 | I22: 3937 | J22: 3678 | K22: 3900 | L22: 3684
F23: Middletown City | G23: 22607 | H23: 21454 | I23: 24160 | J23: 25388 | K23: 28086 | L23: 30345
F24: Minisink Town | G24: 1942 | H24: 2488 | I24: 2981 | J24: 3585 | K24: 4490 | L24: 4621
F25: Unionville Village | G25: 576 | H25: 574 | I25: 548 | J25: 536 | K25: 612 | L25: 592
F26: Monroe Town | G26: 9190 | H26: 14948 | I26: 23035 | J26: 31407 | K26: 39912 | L26: 21387
F27: Harriman Village (portion) | G27: 955 | H27: 796 | I27: 2288 | J27: 2252 | K27: 2424 | L27: 2714
F28: Monroe Village | G28: 4439 | H28: 5996 | I28: 6672 | J28: 7780 | K28: 8364 | L28: 9343
F29: Montgomery Town | G29: 13995 | H29: 16576 | I29: 18501 | J29: 20891 | K29: 22606 | L29: 23322
F30: Maybrook Village | G30: 1536 | H30: 2007 | I30: 2802 | J30: 3084 | K30: 2958 | L30: 3150
F31: Montgomery Village | G31: 1533 | H31: 2316 | I31: 2696 | J31: 3636 | K31: 3814 | L31: 3834
F32: Walden Village | G32: 5277 | H32: 5659 | I32: 5836 | J32: 6164 | K32: 6978 | L32: 6818
F33: Mount Hope Town | G33: 2966 | H33: 4398 | I33: 5971 | J33: 6639 | K33: 7018 | L33: 6537
F34: Otisville Village | G34: 933 | H34: 953 | I34: 1078 | J34: 989 | K34: 1068 | L34: 989
... F37: New Windsor Town | G37: 16650 | H37: 19534 | I37: 22937 | J37: 22866 | K37: 25244 | L37: 27805
F38: Palm Tree Town | G38: N/A | H38: N/A | I38: N/A | J38: N/A | K38: N/A | L38: 32954
F39: Kiryas Joel Village | G39: 0 | H39: 2088 | I39: 7437 | J39: 13138 | K39: 20175 | L39: 32954
F40: Port Jervis City | G40: 8852 | H40: 8699 | I40: 9060 | J40: 8860 | K40: 8828 | L40: 8775
F41: Tuxedo Town | G41: 2967 | H41: 3069 | I41: 3023 | J41: 3334 | K41: 3624 | L41: 3811
F42: Tuxedo Village | G42: 861 | H42: 809 | I42: 706 | J42: 731 | K42: 623 | L42: 645
...

Sheet Population Growth
A1: Name | B1: Population Growth by Municipality, 2000–2020
A2: Table/Figure/Both | B2: Both
A3: Object ID | B3: =IF($B$1="","",_xlfn.XLOOKUP($B$1,Master!$F$2:$F$321,Master!$G$2:$G$321,"")) -> tbl-pop-growth
A4: Figure ID | B4: =IF($B$1="","",_xlfn.XLOOKUP($B$1,Master!$F$2:$F$321,Master!$H$2:$H$321,"")) -> fig-pop-growth | F4: text | G4: number | H4: number | I4: number | J4: percent1 | K4: percent1 | L4: percent1
A5: Table Rules | E5: Enter Data | F5: Geographic Area | G5: Total Population | J5: Percent Change
A6: Multilevel Headers | B6: FALSE | G6: 2000 | H6: 2010 | I6: 2020 | J6: 2000-2010 | K6: 2010-2020 | L6: 2000-20
F7: Orange County | G7: 341367 | H7: 372813 | I7: 401310 | J7: 9.2 | K7: 7.6 | L7: 17.6
F8: Blooming Grove Town | G8: 17351 | H8: 18028 | I8: 18811 | J8: 3.9 | K8: 4.3 | L8: 8.4
A9: Figure Rules | F9: South Blooming Grove Village | G9: n/a | H9: 3234 | I9: 3973 | J9: N/A | K9: 22.9 | L9: N/A
A10: Figure Type | F10: Washingtonville Village | G10: 5851 | H10: 5899 | I10: 5657 | J10: 0.8 | K10: -4.1 | L10: -3.3
A11: X Column | F11: Chester Town | G11: 12140 | H11: 11981 | I11: 12646 | J11: -1.3 | K11: 5.6 | L11: 4.2
A12: Y Column | F12: Chester Village | G12: 3445 | H12: 3969 | I12: 3993 | J12: 15.2 | K12: 0.6 | L12: 15.9
A13: X Axis Title | F13: Cornwall Town | G13: 12307 | H13: 12646 | I13: 12884 | J13: 2.8 | K13: 1.9 | L13: 4.7
A14: Y Axis Title | F14: Cornwall-on-Hudson Village | G14: 3058 | H14: 3018 | I14: 3075 | J14: -1.3 | K14: 1.9 | L14: 0.6
A15: Start at Zero | F15: Crawford Town | G15: 7875 | H15: 9316 | I15: 9130 | J15: 18.3 | K15: -2 | L15: 15.9
A16: Pivot For Chart | F16: Deerpark Town | G16: 7858 | H16: 7901 | I16: 7509 | J16: 0.5 | K16: -5 | L16: -4.4
F17: Goshen Town | G17: 12913 | H17: 13687 | I17: 14571 | J17: 6 | K17: 6.5 | L17: 12.8
A18: Source Specifications | F18: Goshen Village | G18: 5676 | H18: 5454 | I18: 5777 | J18: -3.9 | K18: 5.9 | L18: 1.8
A19: Source | B19: Source: US Census Bureau, 2020 Decennial Redistricting Data (PL 94-171), Table P, November 2025 https://data.census.gov/table/DECENNIALPL2020.P1?q=PL+94-171&g=050XX00US36071 | F19: Greenville Town | G19: 3800 | H19: 4616 | I19: 4689 | J19: 21.5 | K19: 1.6 | L19: 23.4
F20: Hamptonburgh Town | G20: 4686 | H20: 5561 | I20: 5489 | J20: 18.7 | K20: -1.3 | L20: 17.1
A21: Note Specfications | F21: Highlands Town | G21: 12484 | H21: 12492 | I21: 12939 | J21: 0.1 | K21: 3.6 | L21: 3.6
A22: Note | B22: Note: Town totals include Village totals; Villages of South Blooming Grove and Woodbury were incorporated in 2006; Town of Palm Tree was incorporated in 2017 and made coterminous to the Village of Kiryas Joel thereafter. Prior to incorporation of Town of Palm Tree, the Village of Kiryas Joel was incorporated within the boundaries of the Town of Monroe. | F22: Highland Falls Village | G22: 3678 | H22: 3900 | I22: 3684 | J22: 6 | K22: -5.5 | L22: 0.2
F23: Middletown City | G23: 25388 | H23: 28086 | I23: 30345 | J23: 10.6 | K23: 8 | L23: 19.5
F24: Minisink Town | G24: 3585 | H24: 4490 | I24: 4621 | J24: 25.2 | K24: 2.9 | L24: 28.9
F25: Unionville Village | G25: 536 | H25: 612 | I25: 592 | J25: 14.2 | K25: -3.3 | L25: 10.4
F26: Monroe Town | G26: 31407 | H26: 39912 | I26: 21387 | J26: 27.1 | K26: -46.4 | L26: -31.9
F27: Harriman Village (portion) | G27: 2252 | H27: 2424 | I27: 2714 | J27: 7.6 | K27: 12 | L27: 20.5
F28: Monroe Village | G28: 7780 | H28: 8364 | I28: 9343 | J28: 7.5 | K28: 11.7 | L28: 20.1
F29: Montgomery Town | G29: 20891 | H29: 22606 | I29: 23322 | J29: 8.2 | K29: 3.2 | L29: 11.6
F30: Maybrook Village | G30: 3084 | H30: 2958 | I30: 3150 | J30: -4.1 | K30: 6.5 | L30: 2.1
F31: Montgomery Village | G31: 3636 | H31: 3814 | I31: 3834 | J31: 4.9 | K31: 0.5 | L31: 5.4
F32: Walden Village | G32: 6164 | H32: 6978 | I32: 6818 | J32: 13.2 | K32: -2.3 | L32: 10.6
F33: Mount Hope Town | G33: 6639 | H33: 7018 | I33: 6537 | J33: 5.7 | K33: -6.9 | L33: -1.5
F34: Otisville Village | G34: 989 | H34: 1068 | I34: 989 | J34: 8 | K34: -7.4 | L34: 0
... F37: New Windsor Town | G37: 22866 | H37: 25244 | I37: 27805 | J37: 10.4 | K37: 10.1 | L37: 21.6
F38: Palm Tree Town | G38: N/A | H38: N/A | I38: 32954 | J38: N/A | K38: N/A | L38: N/A
F39: Kiryas Joel Village | G39: 13138 | H39: 20175 | I39: 32954 | J39: 53.6 | K39: 63.3 | L39: 150.8
F40: Port Jervis City | G40: 8860 | H40: 8828 | I40: 8775 | J40: -0.4 | K40: -0.6 | L40: -1
F41: Tuxedo Town | G41: 3334 | H41: 3624 | I41: 3811 | J41: 8.7 | K41: 5.2 | L41: 14.3
F42: Tuxedo Village | G42: 731 | H42: 623 | I42: 645 | J42: -14.8 | K42: 3.5 | L42: -11.8
...

Sheet Population and Housing Unit Den
A1: Name | B1: Population and Housing Unit Density by Municipality, 2023
A2: Table/Figure/Both | B2: Both
A3: Object ID | B3: =IF($B$1="","",_xlfn.XLOOKUP($B$1,Master!$F$2:$F$321,Master!$G$2:$G$321,"")) -> tbl-pop-housing-density
A4: Figure ID | B4: =IF($B$1="","",_xlfn.XLOOKUP($B$1,Master!$F$2:$F$321,Master!$H$2:$H$321,"")) -> fig-pop-housing-density | F4: text | G4: percent1 | H4: percent1 | I4: percent1
A5: Table Rules | E5: Enter Data | F5: Geographic Area | G5: Land Area per Square Mile | H5: People per Square Mile | I5: Housing Units per Square Mile
A6: Multilevel Headers | B6: FALSE | F6: Orange County | G6: 812.3 | H6: 497.1 | I6: 182.8
F7: Blooming Grove Town | G7: 34.7 | H7: 537.6 | I7: 198.2
F8: South Blooming Grove Village | G8: 4.7 | H8: 829.1 | I8: 297
A9: Figure Rules | F9: Washingtonville Village | G9: 2.5 | H9: 2253.2 | I9: 860.6
A10: Figure Type | F10: Chester Town | G10: 25.1 | H10: 503.8 | I10: 190.1
A11: X Column | F11: Chester Village | G11: 2.2 | H11: 1884.7 | I11: 784.7
A12: Y Column | F12: Cornwall Town | G12: 26.7 | H12: 480.2 | I12: 201.3
A13: X Axis Title | F13: Cornwall-on-Hudson Village | G13: 2 | H13: 1530.7 | I13: 671.9
A14: Y Axis Title | F14: Crawford Town | G14: 40 | H14: 227.3 | I14: 77.3
A15: Start at Zero | F15: Deerpark Town | G15: 66.5 | H15: 112.4 | I15: 50.3
A16: Pivot For Chart | F16: Goshen Town | G16: 43.6 | H16: 331.4 | I16: 123.1
F17: Goshen Village | G17: 3.3 | H17: 1732.2 | I17: 778
A18: Source Specifications | F18: Greenville Town | G18: 38.9 | H18: 120.3 | I18: 45.6
A19: Source | B19: Source: US Census Bureau, Quick Facts, November 2025 https://www.census.gov/quickfacts/orangecountynewyork | F19: Hamptonburgh Town | G19: 26.8 | H19: 205.8 | I19: 68.8
F20: Highlands Town | G20: 30.4 | H20: 424.1 | I20: 139.5
A21: Note Specfications | F21: Highland Falls Village | G21: 1.1 | H21: 3390.8 | I21: 1649.5
A22: Note | B22: Note: Town totals include Village totals. Land area calculated as of 2020 Census. Population density and housing unit density calculated using 2019-2023 estimates divided by land area. | F22: Middletown City | G22: 5.3 | H22: 5692.5 | I22: 2075
F23: Minisink Town | G23: 23 | H23: 202.1 | I23: 70.8
F24: Unionville Village | G24: 0.3 | H24: 2206.5 | I24: 758.1
F25: Monroe Town | G25: 18.6 | H25: 1148.2 | I25: 398.7
F26: Harriman Village (portion) | G26: 0.5 | H26: 4352.1 | I26: 1829.2
F27: Monroe Village | G27: 3.5 | H27: 2712.3 | I27: 850.7
F28: Montgomery Town | G28: 50.3 | H28: 462.3 | I28: 178.5
F29: Maybrook Village | G29: 1.4 | H29: 2331.1 | I29: 1125.2
F30: Montgomery Village | G30: 1.4 | H30: 2695 | I30: 1134.8
F31: Walden Village | G31: 2 | H31: 3487.8 | I31: 1462.9 | K31: `
F32: Mount Hope Town | G32: 25.1 | H32: 258.7 | I32: 91.1
F33: Otisville Village | G33: 0.8 | H33: 1592.1 | I33: 615.8
F34: Newburgh City | G34: 3.8 | H34: 7519.4 | I34: 3050.9
F35: Newburgh Town | G35: 43.4 | H35: 734.9 | I35: 284.9
F36: New Windsor Town | G36: 34.1 | H36: 815.2 | I36: 332.6
F37: Palm Tree Town | G37: 1.5 | H37: 25049.3 | I37: 5056.9
F38: Kiryas Joel Village | G38: 1.5 | H38: 25049.3 | I38: 5056.9
F39: Port Jervis City | G39: 2.5 | H39: 3442.3 | I39: 1539.9
F40: Tuxedo Town | G40: 47.1 | H40: 80 | I40: 37.5
...

Sheet Pop of Mun by Sex and Age
A1: Name | B1: Population of Municipalities by Sex and Age, 2023
A2: Table/Figure/Both | B2: Both
A3: Object ID | B3: =IF($B$1="","",_xlfn.XLOOKUP($B$1,Master!$F$2:$F$321,Master!$G$2:$G$321,"")) -> tbl-pop-sex-age
A4: Figure ID | B4: =IF($B$1="","",_xlfn.XLOOKUP($B$1,Master!$F$2:$F$321,Master!$H$2:$H$321,"")) -> fig-pop-sex-age | F4: text | G4: number | H4: number | I4: number | J4: number | K4: number | L4: number | M4: number | N4: number | O4: number | P4: number | Q4: number | R4: number
A5: Table Rules | E5: Enter Data | F5: Geographic Area | G5: Total Population | J5: Population >18 years | M5: Population Age 15-44 year | P5: Population 65+ years
A6: Multilevel Headers | B6: TRUE | G6: Total | H6: Male | I6: Female | J6: Total | K6: Male | L6: Female | M6: Total | N6: Male | O6: Female | P6: Total | Q6: Male | R6: Female
F7: Orange County | G7: 403840 | H7: 201512 | I7: 202328 | J7: 103740 | K7: 53161 | L7: 50579 | M7: 157903 | N7: 80408 | O7: 77495 | P7: 57945 | Q7: 26221 | R7: 31724
F8: Blooming Grove Town | G8: 18672 | H8: 9133 | I8: 9539 | J8: 5333 | K8: 2906 | L8: 2427 | M8: 7299 | N8: 3507 | O8: 3792 | P8: 2275 | Q8: 1093 | R8: 1182
A9: Figure Rules | F9: South Blooming Grove Village | G9: 3880 | H9: 1933 | I9: 1947 | J9: 1658 | K9: 774 | L9: 884 | M9: 1552 | N9: 738 | O9: 814 | P9: 337 | Q9: 188 | R9: 149
A10: Figure Type | F10: Washingtonville Village | G10: 5723 | H10: 2883 | I10: 2840 | J10: 1287 | K10: 740 | L10: 547 | M10: 2353 | N10: 1384 | O10: 969 | P10: 885 | Q10: 377 | R10: 508
A11: X Column | F11: Chester Town | G11: 12621 | H11: 5839 | I11: 6782 | J11: 2702 | K11: 1098 | L11: 1604 | M11: 5120 | N11: 2506 | O11: 2614 | P11: 1794 | Q11: 726 | R11: 1068
A12: Y Column | F12: Chester Village | G12: 4052 | H12: 1961 | I12: 2091 | J12: 738 | K12: 369 | L12: 369 | M12: 1797 | N12: 1018 | O12: 779 | P12: 550 | Q12: 221 | R12: 329
A13: X Axis Title | F13: Cornwall Town | G13: 12801 | H13: 6218 | I13: 6583 | J13: 2714 | K13: 1263 | L13: 1451 | M13: 4709 | N13: 2289 | O13: 2420 | P13: 2504 | Q13: 1207 | R13: 1297
A14: Y Axis Title | F14: Cornwall-on-Hudson Village | G14: 3046 | H14: 1460 | I14: 1586 | J14: 593 | K14: 228 | L14: 365 | M14: 1087 | N14: 484 | O14: 603 | P14: 552 | Q14: 233 | R14: 319
A15: Start at Zero | F15: Crawford Town | G15: 9097 | H15: 4732 | I15: 4365 | J15: 2086 | K15: 1380 | L15: 706 | M15: 3571 | N15: 1701 | O15: 1870 | P15: 1183 | Q15: 495 | R15: 688
A16: Pivot For Chart | F16: Deerpark Town | G16: 7471 | H16: 3753 | I16: 3718 | J16: 1512 | K16: 494 | L16: 1018 | M16: 2498 | N16: 1298 | O16: 1200 | P16: 1665 | Q16: 925 | R16: 740
F17: Goshen Town | G17: 14463 | H17: 7390 | I17: 7073 | J17: 2871 | K17: 1373 | L17: 1498 | M17: 4911 | N17: 2696 | O17: 2215 | P17: 3063 | Q17: 1307 | R17: 1756
A18: Source Specifications | F18: Goshen Village | G18: 5751 | H18: 2745 | I18: 3006 | J18: 1108 | K18: 594 | L18: 514 | M18: 1675 | N18: 812 | O18: 863 | P18: 1532 | Q18: 591 | R18: 941
A19: Source | B19: Source: US Census Bureau, American Community Survey 2019–2023 5-Year Population Estimates, Table S0101-Age and Sex, November 2025 https://data.census.gov/table?q=S0101+Orange+County,+NY&g=050XX00US36071 | F19: Greenville Town | G19: 4680 | H19: 2458 | I19: 2222 | J19: 1167 | K19: 659 | L19: 508 | M19: 1869 | N19: 1015 | O19: 854 | P19: 610 | Q19: 285 | R19: 325
F20: Hamptonburgh Town | G20: 5507 | H20: 2924 | I20: 2583 | J20: 1280 | K20: 818 | L20: 462 | M20: 1877 | N20: 1033 | O20: 844 | P20: 785 | Q20: 340 | R20: 445
A21: Note Specfications | F21: Highlands Town | G21: 12894 | H21: 7397 | I21: 5497 | J21: 3027 | K21: 1700 | L21: 1327 | M21: 6519 | N21: 3791 | O21: 2728 | P21: 1064 | Q21: 553 | R21: 511
A22: Note | B22: Note: Town totals include Village totals. | F22: Highland Falls Village | G22: 3696 | H22: 2000 | I22: 1696 | J22: 773 | K22: 439 | L22: 334 | M22: 1323 | N22: 694 | O22: 629 | P22: 447 | Q22: 176 | R22: 271
F23: Middletown City | G23: 30227 | H23: 15640 | I23: 14587 | J23: 7796 | K23: 4379 | L23: 3417 | M23: 12169 | N23: 6647 | O23: 5522 | P23: 4110 | Q23: 1855 | R23: 2255
F24: Minisink Town | G24: 4648 | H24: 2246 | I24: 2402 | J24: 1277 | K24: 496 | L24: 781 | M24: 1806 | N24: 841 | O24: 965 | P24: 524 | Q24: 332 | R24: 192
F25: Unionville Village | G25: 684 | H25: 282 | I25: 402 | J25: 222 | K25: 61 | L25: 161 | M25: 278 | N25: 114 | O25: 164 | P25: 79 | Q25: 38 | R25: 41
F26: Monroe Town | G26: 21299 | H26: 9782 | I26: 11517 | J26: 5787 | K26: 2800 | L26: 2987 | M26: 7992 | N26: 3423 | O26: 4569 | P26: 3039 | Q26: 1509 | R26: 1530
F27: Harriman Village (portion) | G27: 2089 | H27: 877 | I27: 1212 | J27: 598 | K27: 232 | L27: 366 | M27: 839 | N27: 399 | O27: 440 | P27: 363 | Q27: 117 | R27: 246
F28: Monroe Village | G28: 9466 | H28: 4473 | I28: 4993 | J28: 2552 | K28: 1325 | L28: 1227 | M28: 3867 | N28: 1767 | O28: 2100 | P28: 950 | Q28: 344 | R28: 606
F29: Montgomery Town | G29: 23235 | H29: 11058 | I29: 12177 | J29: 5597 | K29: 2566 | L29: 3031 | M29: 8825 | N29: 4262 | O29: 4563 | P29: 3358 | Q29: 1473 | R29: 1885
F30: Maybrook Village | G30: 3147 | H30: 1451 | I30: 1696 | J30: 507 | K30: 202 | L30: 305 | M30: 1094 | N30: 626 | O30: 468 | P30: 660 | Q30: 273 | R30: 387
F31: Montgomery Village | G31: 3800 | H31: 1722 | I31: 2078 | J31: 962 | K31: 434 | L31: 528 | M31: 1407 | N31: 679 | O31: 728 | P31: 553 | Q31: 186 | R31: 367
F32: Walden Village | G32: 6871 | H32: 3498 | I32: 3373 | J32: 1664 | K32: 868 | L32: 796 | M32: 2710 | N32: 1279 | O32: 1431 | P32: 816 | Q32: 337 | R32: 479
F33: Mount Hope Town | G33: 6500 | H33: 3897 | I33: 2603 | J33: 1080 | K33: 541 | L33: 539 | M33: 2476 | N33: 1540 | O33: 936 | P33: 1079 | Q33: 540 | R33: 539
F34: Otisville Village | G34: 1210 | H34: 623 | I34: 587 | J34: 353 | K34: 148 | L34: 205 | M34: 464 | N34: 267 | O34: 197 | P34: 237 | Q34: 102 | R34: 135
... F52: Woodbury Village | G52: 11437 | H52: 5868 | I52: 5569 | J52: 2930 | K52: 1721 | L52: 1209 | M52: 4484 | N52: 2456 | O52: 2028 | P52: 1287 | Q52: 620 | R52: 667

Sheet POP Mun Race-Eth
A1: Name | B1: Population of Municipalities by Race and Ethnicity, 2020
A2: Table/Figure/Both | B2: Both
A3: Object ID | B3: =IF($B$1="","",_xlfn.XLOOKUP($B$1,Master!$F$2:$F$321,Master!$G$2:$G$321,"")) -> tbl-pop-race-ethnicity
A4: Figure ID | B4: =IF($B$1="","",_xlfn.XLOOKUP($B$1,Master!$F$2:$F$321,Master!$H$2:$H$321,"")) -> fig-pop-race-ethnicity | F4: text | G4: number | H4: number | I4: number | J4: number | K4: number | L4: number | M4: number | N4: number | O4: number | P4: number
A5: Table Rules | E5: Enter Data | F5: Geographic Area | G5: Total Pop | H5: White Alone | I5: Black Alone | J5: American Indian/Alaska Native Alone | K5: Asian Alone | L5: Native Hawaiian/Pacific Islander Alone | M5: Some Other Race Alone | N5: Two or More Races | O5: Hispanic or Latino | P5: Not Hispanic or Latino
A6: Multilevel Headers | B6: FALSE | F6: Orange County | G6: 401310 | H6: 248085 | I6: 45543 | J6: 2949 | K6: 12025 | L6: 185 | M6: 52023 | N6: 40500 | O6: 89744 | P6: 311566
F7: Blooming Grove Town | G7: 18811 | H7: 12738 | I7: 1539 | J7: 121 | K7: 416 | L7: 7 | M7: 1784 | N7: 2206 | O7: 3913 | P7: 14898
F8: South Blooming Grove Village | G8: 3973 | H8: 2786 | I8: 311 | J8: 25 | K8: 52 | L8: 5 | M8: 484 | N8: 310 | O8: 555 | P8: 3418
A9: Figure Rules | F9: Washingtonville Village | G9: 5657 | H9: 3555 | I9: 630 | J9: 26 | K9: 131 | L9: 1 | M9: 590 | N9: 724 | O9: 1466 | P9: 4191
A10: Figure Type | F10: Chester Town | G10: 12646 | H10: 8574 | I10: 1188 | J10: 53 | K10: 513 | L10: 2 | M10: 984 | N10: 1332 | O10: 2446 | P10: 10200
A11: X Column | F11: Chester Village | G11: 3993 | H11: 2287 | I11: 611 | J11: 33 | K11: 212 | L11: 2 | M11: 417 | N11: 431 | O11: 912 | P11: 3081
A12: Y Column | F12: Cornwall Town | G12: 12884 | H12: 10225 | I12: 466 | J12: 37 | K12: 412 | L12: 5 | M12: 585 | N12: 1154 | O12: 1664 | P12: 11220
A13: X Axis Title | F13: Cornwall-on-Hudson Village | G13: 3075 | H13: 2598 | I13: 82 | J13: 9 | K13: 51 | L13: 3 | M13: 65 | N13: 267 | O13: 277 | P13: 2798
A14: Y Axis Title | F14: Crawford Town | G14: 9130 | H14: 7187 | I14: 390 | J14: 38 | K14: 152 | L14: 1 | M14: 439 | N14: 923 | O14: 1370 | P14: 7760
A15: Start at Zero | F15: Deerpark Town | G15: 7509 | H15: 6083 | I15: 240 | J15: 37 | K15: 334 | L15: 3 | M15: 188 | N15: 624 | O15: 657 | P15: 6852
A16: Pivot For Chart | F16: Goshen Town | G16: 14571 | H16: 10315 | I16: 1026 | J16: 68 | K16: 491 | L16: 3 | M16: 1196 | N16: 1472 | O16: 3133 | P16: 11438
F17: Goshen Village | G17: 5777 | H17: 4230 | I17: 303 | J17: 31 | K17: 185 | L17: 2 | M17: 509 | N17: 517 | O17: 1205 | P17: 4572
A18: Source Specifications | F18: Greenville Town | G18: 4689 | H18: 3828 | I18: 164 | J18: 17 | K18: 55 | L18: 0 | M18: 229 | N18: 396 | O18: 626 | P18: 4063
A19: Source | B19: Source: US Census Bureau, 2020 Decennial Redistricting Data (PL 94-171), Table P1-Total Population, November 2025 https://data.census.gov/table/DECENNIALPL2020.P1?q=PL+94-171&g=050XX00US36071 | F19: Hamptonburgh Town | G19: 5489 | H19: 4274 | I19: 189 | J19: 20 | K19: 204 | L19: 0 | M19: 227 | N19: 575 | O19: 797 | P19: 4692
F20: Highlands Town | G20: 12939 | H20: 8655 | I20: 1435 | J20: 137 | K20: 613 | L20: 31 | M20: 893 | N20: 1175 | O20: 2066 | P20: 10873
A21: Note Specfications | F21: Highland Falls Village | G21: 3684 | H21: 2100 | I21: 561 | J21: 54 | K21: 110 | L21: 3 | M21: 441 | N21: 415 | O21: 947 | P21: 2737
A22: Note | B22: Note: Town totals include Village totals | F22: Middletown City | G22: 30345 | H22: 9983 | I22: 7116 | J22: 424 | K22: 1165 | L22: 14 | M22: 7284 | N22: 4359 | O22: 13243 | P22: 17102
F23: Minisink Town | G23: 4621 | H23: 3829 | I23: 177 | J23: 8 | K23: 49 | L23: 0 | M23: 188 | N23: 370 | O23: 618 | P23: 4003
F24: Unionville Village | G24: 592 | H24: 505 | I24: 27 | J24: 0 | K24: 4 | L24: 0 | M24: 23 | N24: 33 | O24: 53 | P24: 539
F25: Monroe Town | G25: 21387 | H25: 13246 | I25: 1685 | J25: 137 | K25: 1221 | L25: 6 | M25: 2833 | N25: 2259 | O25: 5342 | P25: 16045
F26: Harriman Village (total)* | G26: 2714 | H26: 1247 | I26: 495 | J26: 9 | K26: 258 | L26: 5 | M26: 364 | N26: 336 | O26: 783 | P26: 1931
F27: Monroe Village | G27: 9343 | H27: 5528 | I27: 699 | J27: 64 | K27: 530 | L27: 0 | M27: 1544 | N27: 978 | O27: 2790 | P27: 6553
F28: Montgomery Town | G28: 23322 | H28: 16894 | I28: 1842 | J28: 117 | K28: 414 | L28: 6 | M28: 1562 | N28: 2487 | O28: 4320 | P28: 19002
F29: Maybrook Village | G29: 3150 | H29: 1930 | I29: 461 | J29: 11 | K29: 43 | L29: 0 | M29: 286 | N29: 419 | O29: 803 | P29: 2347
F30: Montgomery Village | G30: 3834 | H30: 2896 | I30: 275 | J30: 9 | K30: 61 | L30: 0 | M30: 181 | N30: 412 | O30: 620 | P30: 3214
F31: Walden Village | G31: 6818 | H31: 4533 | I31: 680 | J31: 55 | K31: 130 | L31: 5 | M31: 588 | N31: 827 | O31: 1596 | P31: 5222
F32: Mount Hope Town | G32: 6537 | H32: 4474 | I32: 824 | J32: 28 | K32: 312 | L32: 0 | M32: 387 | N32: 512 | O32: 1143 | P32: 5394
F33: Otisville Village | G33: 969 | H33: 719 | I33: 52 | J33: 3 | K33: 72 | L33: 0 | M33: 34 | N33: 89 | O33: 159 | P33: 810
F34: Newburgh City | G34: 28856 | H34: 6554 | I34: 8167 | J34: 656 | K34: 260 | L34: 24 | M34: 9737 | N34: 3458 | O34: 15085 | P34: 13771
... F49: Woodbury Village | G49: 11526 | H49: 7226 | I49: 942 | J49: 92 | K49: 720 | L49: 15 | M49: 1389 | N49: 1142 | O49: 2458 | P49: 9068

Sheet Employed Civilians by Industry
A1: Name | B1: Employed Civilians by Industry and Municipality, 2023
A2: Table/Figure/Both | B2: Both
A3: Object ID | B3: =IF($B$1="","",_xlfn.XLOOKUP($B$1,Master!$F$2:$F$321,Master!$G$2:$G$321,"")) -> tbl-employed-civilians-industry
A4: Figure ID | B4: =IF($B$1="","",_xlfn.XLOOKUP($B$1,Master!$F$2:$F$321,Master!$H$2:$H$321,"")) -> fig-employed-civilians-industry | F4: text | G4: number | H4: number | I4: number | J4: number | K4: number | L4: number | M4: number | N4: number | O4: number | P4: number | Q4: number | R4: number | S4: number | T4: number
A5: Table Rules | E5: Enter Data | F5: Geographic Area | G5: Civilian Employed Population Age 16+ | H5: Industry
A6: Multilevel Headers | B6: TRUE | H6: Agriculture, Forestry, Fishing, Hunting, Mining | I6: Construction | J6: Manufacturing | K6: Wholesale Trade | L6: Retail Trade | M6: Transportation, Warehousing, Utilities | N6: Information | O6: Finance, Insurance, Real Estate, Rental/Leasing | P6: Professional, Scientific, Management, Administrative, Waste Management | Q6: Educational Services, Health Care, Social Assistance | R6: Arts, Entertainment, Recreation, Accommodation, Food Services | S6: Public Administration | T6: Other Services
F7: Orange County | G7: 184167 | H7: 1278 | I7: 13492 | J7: 11754 | K7: 5470 | L7: 23207 | M7: 12393 | N7: 4268 | O7: 10817 | P7: 18700 | Q7: 50693 | R7: 12127 | S7: 10996 | T7: 8972
F8: Blooming Grove Town | G8: 8167 | H8: 85 | I8: 766 | J8: 369 | K8: 263 | L8: 891 | M8: 375 | N8: 255 | O8: 633 | P8: 692 | Q8: 2359 | R8: 628 | S8: 495 | T8: 356
A9: Figure Rules | F9: South Blooming Grove Village | G9: 1268 | H9: 0 | I9: 103 | J9: 102 | K9: 49 | L9: 169 | M9: 55 | N9: 29 | O9: 99 | P9: 71 | Q9: 355 | R9: 132 | S9: 5 | T9: 99
A10: Figure Type | F10: Washingtonville Village | G10: 2827 | H10: 0 | I10: 120 | J10: 103 | K10: 187 | L10: 251 | M10: 89 | N10: 155 | O10: 288 | P10: 203 | Q10: 800 | R10: 169 | S10: 298 | T10: 164
A11: X Column | F11: Chester Town | G11: 6888 | H11: 25 | I11: 346 | J11: 488 | K11: 283 | L11: 1099 | M11: 648 | N11: 244 | O11: 416 | P11: 790 | Q11: 1327 | R11: 533 | S11: 447 | T11: 242
A12: Y Column | F12: Chester Village | G12: 2488 | H12: 0 | I12: 89 | J12: 111 | K12: 96 | L12: 633 | M12: 263 | N12: 77 | O12: 175 | P12: 108 | Q12: 423 | R12: 260 | S12: 141 | T12: 112
A13: X Axis Title | F13: Cornwall Town | G13: 6425 | H13: 12 | I13: 357 | J13: 452 | K13: 155 | L13: 593 | M13: 207 | N13: 171 | O13: 406 | P13: 799 | Q13: 2023 | R13: 342 | S13: 725 | T13: 183
A14: Y Axis Title | F14: Cornwall-on-Hudson Village | G14: 1656 | H14: 0 | I14: 63 | J14: 156 | K14: 10 | L14: 189 | M14: 87 | N14: 30 | O14: 120 | P14: 148 | Q14: 534 | R14: 74 | S14: 202 | T14: 43
A15: Start at Zero | F15: Crawford Town | G15: 5000 | H15: 58 | I15: 426 | J15: 162 | K15: 180 | L15: 580 | M15: 230 | N15: 149 | O15: 293 | P15: 516 | Q15: 1632 | R15: 255 | S15: 315 | T15: 204
A16: Pivot For Chart | F16: Deerpark Town | G16: 3207 | H16: 76 | I16: 232 | J16: 250 | K16: 52 | L16: 463 | M16: 239 | N16: 74 | O16: 30 | P16: 309 | Q16: 810 | R16: 163 | S16: 192 | T16: 317
F17: Goshen Town | G17: 6373 | H17: 52 | I17: 372 | J17: 590 | K17: 214 | L17: 863 | M17: 270 | N17: 80 | O17: 328 | P17: 744 | Q17: 1875 | R17: 318 | S17: 439 | T17: 228
A18: Source Specifications | F18: Goshen Village | G18: 2703 | H18: 0 | I18: 175 | J18: 103 | K18: 61 | L18: 349 | M18: 127 | N18: 29 | O18: 178 | P18: 335 | Q18: 796 | R18: 232 | S18: 238 | T18: 80
A19: Source | B19: Source: US Census Bureau, American Community Survey 2019–2023 5-Year Population Estimates, S2403-Industry by Sex for the Civilian Employed Population 16 Years and Over, November 2025 https://data.census.gov/table/ACSST5Y2023.S2403?q=S2403+Orange+County,+NY&g=060XX00US3607134550,3607156185,3607148857,3607182755,3607147042,3607148153,3607178839,3607130631,3607 118300,3607175781,3607150045,3607147713,3607147999,3607150848,3607129553,3607107003,3607115308,3607131907,3607118916,3607178366,3607177992,3607119961,3607150034,3607159388_ 160XX00US3646162,3629542,3630752,3655673,3678355,3676210,3634495,3615297,3675803,3682750,3677849,3632325,3647988,3678465,3639853,3618333,3668610,3648142_050XX00US36071 | F19: Greenville Town | G19: 2563 | H19: 55 | I19: 206 | J19: 113 | K19: 36 | L19: 262 | M19: 250 | N19: 63 | O19: 115 | P19: 155 | Q19: 774 | R19: 49 | S19: 304 | T19: 181
F20: Hamptonburgh Town | G20: 2495 | H20: 9 | I20: 368 | J20: 74 | K20: 112 | L20: 249 | M20: 110 | N20: 55 | O20: 113 | P20: 355 | Q20: 598 | R20: 161 | S20: 52 | T20: 239
A21: Note Specfications | F21: Highlands Town | G21: 4373 | H21: 7 | I21: 234 | J21: 202 | K21: 14 | L21: 257 | M21: 568 | N21: 82 | O21: 61 | P21: 632 | Q21: 1291 | R21: 423 | S21: 420 | T21: 182
A22: Note | B22: Note: Town totals include Village totals. Industry titles and their 4-digit codes are based on the North American Industry Classification System (NAICS). The Census industry codes for 2023 and later years are based on the 2022 revision of the NAICS. To allow for the creation of multiyear tables, industry data in the multiyear files (prior to data year 2023) were recoded to the 2022 Census industry codes. We recommend using caution when comparing data coded using 2022 Census industry codes with data coded using Census industry codes prior to data year 2023. | F22: Highland Falls Village | G22: 1770 | H22: 0 | I22: 109 | J22: 85 | K22: 14 | L22: 100 | M22: 135 | N22: 7 | O22: 15 | P22: 312 | Q22: 539 | R22: 207 | S22: 183 | T22: 64
F23: Middletown City | G23: 13664 | H23: 139 | I23: 1041 | J23: 834 | K23: 214 | L23: 1951 | M23: 1113 | N23: 308 | O23: 679 | P23: 1311 | Q23: 3597 | R23: 1028 | S23: 601 | T23: 848
F24: Minisink Town | G24: 2456 | H24: 26 | I24: 101 | J24: 79 | K24: 71 | L24: 189 | M24: 270 | N24: 41 | O24: 134 | P24: 305 | Q24: 837 | R24: 127 | S24: 132 | T24: 144
F25: Unionville Village | G25: 368 | H25: 0 | I25: 19 | J25: 0 | K25: 0 | L25: 43 | M25: 83 | N25: 0 | O25: 35 | P25: 76 | Q25: 80 | R25: 5 | S25: 0 | T25: 27
F26: Monroe Town | G26: 10354 | H26: 7 | I26: 615 | J26: 554 | K26: 200 | L26: 1305 | M26: 544 | N26: 375 | O26: 715 | P26: 1187 | Q26: 2809 | R26: 643 | S26: 714 | T26: 686
F27: Harriman Village (portion) | G27: 1052 | H27: 0 | I27: 82 | J27: 71 | K27: 8 | L27: 140 | M27: 38 | N27: 9 | O27: 18 | P27: 27 | Q27: 333 | R27: 73 | S27: 40 | T27: 113
F28: Monroe Village | G28: 4852 | H28: 7 | I28: 299 | J28: 294 | K28: 45 | L28: 606 | M28: 276 | N28: 75 | O28: 317 | P28: 526 | Q28: 1482 | R28: 440 | S28: 310 | T28: 175
F29: Montgomery Town | G29: 11292 | H29: 127 | I29: 922 | J29: 819 | K29: 262 | L29: 1205 | M29: 1071 | N29: 214 | O29: 579 | P29: 859 | Q29: 2911 | R29: 865 | S29: 933 | T29: 525
F30: Maybrook Village | G30: 1807 | H30: 0 | I30: 88 | J30: 126 | K30: 32 | L30: 193 | M30: 367 | N30: 13 | O30: 119 | P30: 70 | Q30: 359 | R30: 187 | S30: 168 | T30: 85
F31: Montgomery Village | G31: 1871 | H31: 0 | I31: 155 | J31: 130 | K31: 76 | L31: 190 | M31: 101 | N31: 29 | O31: 110 | P31: 146 | Q31: 462 | R31: 180 | S31: 263 | T31: 29
F32: Walden Village | G32: 3220 | H32: 15 | I32: 208 | J32: 202 | K32: 84 | L32: 228 | M32: 422 | N32: 73 | O32: 152 | P32: 365 | Q32: 1031 | R32: 216 | S32: 99 | T32: 125
F33: Mount Hope Town | G33: 2690 | H33: 3 | I33: 292 | J33: 123 | K33: 63 | L33: 350 | M33: 212 | N33: 35 | O33: 88 | P33: 235 | Q33: 823 | R33: 178 | S33: 162 | T33: 126
F34: Otisville Village | G34: 500 | H34: 0 | I34: 97 | J34: 25 | K34: 6 | L34: 35 | M34: 45 | N34: 0 | O34: 17 | P34: 36 | Q34: 142 | R34: 52 | S34: 27 | T34: 18
... F52: Woodbury Village | G52: 5288 | H52: 0 | I52: 393 | J52: 170 | K52: 98 | L52: 627 | M52: 444 | N52: 182 | O52: 349 | P52: 829 | Q52: 1464 | R52: 289 | S52: 269 | T52: 174

Sheet Employed Civilian Occupations b
A1: Name | B1: Employed Civilian Occupations by Municipality, 2023
A2: Table/Figure/Both | B2: Both
A3: Object ID | B3: =IF($B$1="","",_xlfn.XLOOKUP($B$1,Master!$F$2:$F$321,Master!$G$2:$G$321,"")) -> tbl-employed-civilian-occupations
A4: Figure ID | B4: =IF($B$1="","",_xlfn.XLOOKUP($B$1,Master!$F$2:$F$321,Master!$H$2:$H$321,"")) -> fig-employed-civilian-occupations | F4: text | G4: number | H4: number | I4: number | J4: number | K4: number | L4: number
A5: Table Rules | E5: Enter Data | F5: Geographic Area | G5: Civilian Employed Population Age 16+ | H5: Occupations
A6: Multilevel Headers | B6: TRUE | H6: Management, Business, Science and Arts | I6: Service | J6: Sales and Office | K6: Natural Resources, Construction, Maintenance | L6: Production, Transportation, Material Moving
F7: Orange County | G7: 184167 | H7: 74036 | I7: 32806 | J7: 40121 | K7: 16708 | L7: 20496
F8: Blooming Grove Town | G8: 8167 | H8: 3370 | I8: 1503 | J8: 1872 | K8: 950 | L8: 472
A9: Figure Rules | F9: South Blooming Grove Village | G9: 1268 | H9: 550 | I9: 194 | J9: 339 | K9: 118 | L9: 67
A10: Figure Type | F10: Washingtonville Village | G10: 2827 | H10: 1117 | I10: 695 | J10: 695 | K10: 195 | L10: 125
A11: X Column | F11: Chester Town | G11: 6888 | H11: 3206 | I11: 741 | J11: 1792 | K11: 447 | L11: 702
A12: Y Column | F12: Chester Village | G12: 2488 | H12: 927 | I12: 295 | J12: 824 | K12: 125 | L12: 317
A13: X Axis Title | F13: Cornwall Town | G13: 6425 | H13: 3459 | I13: 930 | J13: 1116 | K13: 522 | L13: 398
A14: Y Axis Title | F14: Cornwall-on-Hudson Village | G14: 1656 | H14: 885 | I14: 259 | J14: 276 | K14: 83 | L14: 153
A15: Start at Zero | F15: Crawford Town | G15: 5000 | H15: 2041 | I15: 842 | J15: 1090 | K15: 588 | L15: 439
A16: Pivot For Chart | F16: Deerpark Town | G16: 3207 | H16: 915 | I16: 505 | J16: 1094 | K16: 267 | L16: 426
F17: Goshen Town | G17: 6373 | H17: 3107 | I17: 948 | J17: 1322 | K17: 558 | L17: 438
A18: Source Specifications | F18: Goshen Village | G18: 2703 | H18: 1151 | I18: 600 | J18: 486 | K18: 199 | L18: 267
A19: Source | B19: Source: US Census Bureau, American Community Survey 2019–2023 5-Year Population Estimates, S2401-Occupation by Sex for the Civilian Employed Population 16 Years and Over, November 2025 https://data.census.gov/table/ACSST5Y2023.S2401?q=S2401+Orange+County,+NY&g=060XX00US3607134550,3607156185,3 607148857,3607182755,3607147042,3607148153,3607178839,3607130631,3607118300,3607175781,3607150045,3607 147713,3607147999,3607150848,3607129553,3607107003,3607115308,3607131907,3607118916,3607178366,3607177 992,3607119961,3607150034,3607159388_160XX00US3646162,3629542,3630752,3655673,3678355,3676210,3634495,3 615297,3675803,3682750,3677849,3632325,3647988,3678465,3639853,3618333,3668610,3648142_050XX00US36071 | F19: Greenville Town | G19: 2563 | H19: 1131 | I19: 450 | J19: 410 | K19: 182 | L19: 390
F20: Hamptonburgh Town | G20: 2495 | H20: 998 | I20: 421 | J20: 408 | K20: 450 | L20: 218
A21: Note Specfications | F21: Highlands Town | G21: 4373 | H21: 1906 | I21: 661 | J21: 934 | K21: 325 | L21: 547
